Workbook

Sheet 1_raw_log
A1: txn_id | B1: txn_date_time | C1: branch_code | D1: product_code | E1: cust_id | F1: channel | G1: campaign_code | H1: currency | I1: amount_local | J1: sales_person_id | K1: status
A2: T00001 | B2: 45659.438 | C2: B01 | D2: P06 | E2: 55691590 | F2: Branch | H2: USD | I2: 602000 | J2: E105 | K2: Completed
A3: T00002 | B3: 45660.396 | C3: B01 | D3: P04 | E3: 1809923365 | F3: Branch | H3: HKD | I3: 484000 | J3: E101 | K3: Completed
A4: T00003 | B4: 45660.403 | C4: B02 | D4: P03 | E4: 0057825472 | F4: Branch | H4: HKD | I4: 874000 | J4: E104 | K4: Completed
A5: T00004 | B5: 45660.444 | C5: B03 | D5: P04 | E5: 7667641457 | F5: Mobile App | H5: USD | I5: 46000 | K5: Completed
A6: T00005 | B6: 45660.719 | C6: B03 | D6: P02 | E6: 8383656346 | F6: Phone Banking | H6: USD | I6: 39000 | J6: E109 | K6: Completed
A7: T00006 | B7: 45660.722 | C7: B01 | D7: P07 | E7: 4100023781 | F7: Phone Banking | H7: USD | I7: 213000 | J7: E108 | K7: Completed
A8: T00007 | B8: 45660.826 | C8: B03 | D8: P02 | E8: 2751672943 | F8: Mobile App | H8: USD | I8: 197000 | K8: Completed
A9: T00008 | B9: 45663.427 | C9: B01 | D9: P01 | E9: 4100023781 | F9: Branch | H9: USD | I9: 25000 | J9: E101 | K9: Completed
A10: T00009 | B10: 45663.472 | C10: B05 | D10: P04 | E10: 5637223790 | F10: Branch | H10: USD | I10: 32000 | J10: E107 | K10: Completed
A11: T00010 | B11: 45663.583 | C11: B02 | D11: P02 | E11: 53083943 | F11: Branch | H11: USD | I11: 87000 | J11: E103 | K11: Completed
A12: T00011 | B12: 45663.611 | C12: B02 | D12: P04 | E12: 8523286479 | F12: Branch | H12: HKD | I12: 437000 | J12: E103 | K12: Completed
A13: T00012 | B13: 45663.674 | C13: B01 | D13: P06 | E13: 3179016710 | F13: Branch | H13: HKD | I13: 577000 | J13: E101 | K13: Cancelled
A14: T00013 | B14: 45664.438 | C14: B02 | D14: P04 | E14: 4256229846 | F14: Mobile App | H14: USD | I14: 18000 | K14: Cancelled
A15: T00014 | B15: 45664.59 | C15: B02 | D15: P02 | E15: 0086890319 | F15: Branch | H15: HKD | I15: 304000 | J15: E104 | K15: Completed
A16: T00015 | B16: 45664.92 | C16: B02 | D16: P01 | E16: 2531925273 | F16: Mobile App | H16: CNY | I16: 136000 | K16: Completed
A17: T00016 | B17: 45665.392 | C17: B03 | D17: P07 | E17: 8585205808 | F17: Branch | H17: USD | I17: 65000 | J17: E109 | K17: Completed
A18: T00017 | B18: 45665.604 | C18: B02 | D18: P04 | E18: 2277513075 | F18: Phone Banking | H18: HKD | I18: 788000 | J18: E103 | K18: Completed
A19: T00018 | B19: 45666.49 | C19: B01 | D19: P03 | E19: 0017404366 | F19: Branch | H19: USD | I19: 41000 | J19: E108 | K19: Completed
A20: T00019 | B20: 45666.545 | C20: B02 | D20: P03 | E20: 2531925273 | F20: Branch | H20: USD | I20: 109000 | J20: E103 | K20: Completed
A21: T00020 | B21: 45666.573 | C21: B03 | D21: P07 | E21: 7569827088 | F21: Phone Banking | H21: USD | I21: 171000 | J21: E109 | K21: Completed
A22: T00021 | B22: 45666.58 | C22: B02 | D22: P08 | E22: 4085391267 | F22: Branch | H22: HKD | I22: 998000 | J22: E103 | K22: Completed
A23: T00022 | B23: 45666.611 | C23: B05 | D23: P03 | E23: 45128803 | F23: Mobile App | H23: HKD | I23: 80000 | J23: E107 | K23: Completed
A24: T00023 | B24: 45666.642 | C24: B03 | D24: P08 | E24: 8487706006 | F24: Branch | H24: HKD | I24: 211000 | J24: E103 | K24: Completed
A25: T00024 | B25: 45666.681 | C25: B02 | D25: P08 | E25: 1272232039 | F25: Mobile App | H25: HKD | I25: 4797000 | K25: Completed
A26: T00025 | B26: 45667.385 | C26: B01 | D26: P02 | E26: 4309083358 | F26: Branch | H26: USD | I26: 70000 | J26: E14 | K26: Completed
A27: T00026 | B27: 45667.472 | C27: B02 | D27: P08 | E27: 8355315526 | F27: Mobile App | H27: USD | I27: 185000 | J27: E104 | K27: Completed
A28: T00027 | B28: 45670.688 | C28: B02 | D28: P04 | E28: 1272232039 | F28: Branch | H28: HKD | I28: 1997000 | J28: E104 | K28: Completed
A29: T00028 | B29: 45670.688 | C29: B03 | D29: P03 | E29: 8585205808 | F29: Branch | H29: HKD | I29: 148000 | J29: E105 | K29: Completed
A30: T00029 | B30: 45670.74 | C30: B02 | D30: P05 | E30: 53083943 | F30: Branch | H30: USD | I30: 23000 | J30: E104 | K30: Completed
A31: T00030 | B31: 45671.538 | C31: B02 | D31: P02 | E31: 3207719945 | F31: Phone Banking | H31: USD | I31: 225000 | J31: e104 | K31: Cancelled
A32: T00031 | B32: 45671.656 | C32: B02 | D32: P02 | E32: 8355315526 | F32: Phone Banking | H32: USD | I32: 16000 | J32: E104 | K32: Completed
A33: T00032 | B33: 45672.726 | C33: B01 | D33: P06 | E33: 4387664751 | F33: Mobile App | G33: CMP-CNY25 | H33: USD | I33: 35000 | K33: Completed
A34: T00033 | B34: 45673.403 | C34: B03 | D34: P06 | E34: 8487706006 | F34: Phone Banking | G34: CMP-CNY25 | H34: USD | I34: 763000 | J34: E109 | K34: Completed
A35: T00034 | B35: 45673.462 | C35: B01 | D35: P07 | E35: 17885621 | F35: Branch | G35: CMP-CNY25 | H35: USD | I35: 75000 | J35: E101 | K35: Completed
A36: T00035 | B36: 45673.469 | C36: B01 | D36: P02 | E36: 0032025226 | F36: Branch | H36: USD | I36: 61000 | J36: E101 | K36: Completed
A37: T00036 | B37: 45673.594 | C37: B02 | D37: P03 | E37: 0044509861 | F37: Phone Banking | G37: CMP-CNY25 | H37: HKD | I37: 2223000 | J37: E1033 | K37: Completed
A38: T00037 | B38: 45674.597 | C38: B01 | D38: P08 | E38: 55245666 | F38: Mobile App | G38: CMP-CNY25 | H38: HKD | I38: 1349000 | K38: Completed
A39: T00038 | B39: 45674.691 | C39: B05 | D39: P04 | E39: 5637223790 | F39: Mobile App | H39: USD | I39: 23000 | J39: E110 | K39: Completed
A40: T00039 | B40: 45674.771 | C40: B02 | D40: P01 | E40: 4206911990 | F40: Mobile App | G40: CMP-CNY25 | H40: USD | I40: 113000 | K40: Completed
...

Sheet 2_enriched_log
A1: txn_id | B1: txn_date_time | C1: branch_code | D1: product_code | E1: cust_id | F1: channel | G1: campaign_code | H1: currency | I1: amount_local | J1: sales_person_id | K1: status | L1: txn_date | M1: txn_time | N1: year | O1: quarter | P1: month | Q1: iso_week | R1: weekday | S1: day_part | T1: branch_code_std | U1: branch_info_since | V1: branch_name | W1: region | X1: branch_status | Y1: product_code_std | Z1: product_name | AA1: product_category | AB1: product_risk_level | AC1: fee_rate | AD1: cust_id_std | AE1: cust_name | AF1: cust_dob | AG1: cust_age_at_sale | AH1: cust_gender | AI1: cust_info_since | AJ1: cust_segment | AK1: cust_risk_profile | AL1: currency_std | AM1: fx_rate_date | AN1: fx_rate_to_hkd | AO1: amount_hkd | AP1: sales_person_id_std | AQ1: sales_person_check | AR1: sales_person_id_corrected | AS1: sales_person_name
A2: =IF(ISBLANK('1_raw_log'!A2),"",'1_raw_log'!A2) | B2: =IF(ISBLANK('1_raw_log'!B2),"",'1_raw_log'!B2) | C2: =IF(ISBLANK('1_raw_log'!C2),"",'1_raw_log'!C2) | D2: =IF(ISBLANK('1_raw_log'!D2),"",'1_raw_log'!D2) | E2: =IF(ISBLANK('1_raw_log'!E2),"",'1_raw_log'!E2) | F2: =IF(ISBLANK('1_raw_log'!F2),"",'1_raw_log'!F2) | G2: =IF(ISBLANK('1_raw_log'!G2),"",'1_raw_log'!G2) | H2: =IF(ISBLANK('1_raw_log'!H2),"",'1_raw_log'!H2) | ... K2: =IF(ISBLANK('1_raw_log'!K2),"",'1_raw_log'!K2) | L2: =INT(B2) | M2: =ROUND(MOD(B2,1)*1440,0)/1440 | N2: =IFERROR(INDEX('3_ref_date'!$B:$B,MATCH(L2,'3_ref_date'!$A:$A,0)),"NOT FOUND") | O2: =IFERROR(INDEX('3_ref_date'!$C:$C,MATCH(L2,'3_ref_date'!$A:$A,0)),"NOT FOUND") | P2: =IFERROR(INDEX('3_ref_date'!$D:$D,MATCH(L2,'3_ref_date'!$A:$A,0)),"NOT FOUND") | Q2: =IFERROR(INDEX('3_ref_date'!$E:$E,MATCH(L2,'3_ref_date'!$A:$A,0)),"NOT FOUND") | R2: =IFERROR(INDEX('3_ref_date'!$F:$F,MATCH(L2,'3_ref_date'!$A:$A,0)),"NOT FOUND") | S2: =IFERROR(INDEX('4_ref_time'!$D:$D,MATCH(ROUND(M2*1440,0),'4_ref_time'!$A:$A,0)),"NOT FOUND") | T2: =UPPER(TRIM(C2)) | U2: =IF(_xlfn.MAXIFS('6_3nf_branch_history'!$B$2:$B$50,'6_3nf_branch_history'!$A$2:$A$50,T2,'6_3nf_branch_history'!$B$2:$B$50,"<="&L2)=0,"NOT FOUND",_xlfn.MAXIFS('6_3nf_branch_history'!$B$2:$B$50,'6_3nf_branch_history'!$A$2:$A$50,T2,'6_3nf_branch_history'!$B$2:$B$50,"<="&L2)) | V2: =IF(U2="NOT FOUND","NOT FOUND",INDEX('6_3nf_branch_history'!$C:$C,SUMPRODUCT(('6_3nf_branch_history'!$A$2:$A$50=T2)*('6_3nf_branch_history'!$B$2:$B$50=U2)*ROW('6_3nf_branch_history'!$A$2:$A$50)))) | W2: =IF(U2="NOT FOUND","NOT FOUND",INDEX('6_3nf_branch_history'!$D:$D,SUMPRODUCT(('6_3nf_branch_history'!$A$2:$A$50=T2)*('6_3nf_branch_history'!$B$2:$B$50=U2)*ROW('6_3nf_branch_history'!$A$2:$A$50)))) | X2: =IF(U2="NOT FOUND","NOT FOUND",INDEX('6_3nf_branch_history'!$E:$E,SUMPRODUCT(('6_3nf_branch_history'!$A$2:$A$50=T2)*('6_3nf_branch_history'!$B$2:$B$50=U2)*ROW('6_3nf_branch_history'!$A$2:$A$50)))) | Y2: =UPPER(TRIM(D2)) | Z2: =IFERROR(INDEX('7_3nf_product'!$B:$B,MATCH(Y2,'7_3nf_product'!$A:$A,0)),"NOT FOUND") | AA2: =IFERROR(INDEX('7_3nf_product'!$C:$C,MATCH(Y2,'7_3nf_product'!$A:$A,0)),"NOT FOUND") | AB2: =IFERROR(INDEX('7_3nf_product'!$D:$D,MATCH(Y2,'7_3nf_product'!$A:$A,0)),"NOT FOUND") | AC2: =IFERROR(INDEX('7_3nf_product'!$E:$E,MATCH(Y2,'7_3nf_product'!$A:$A,0)),"NOT FOUND") | AD2: =IF(LEN(TRIM(E2))=10,TRIM(E2),IF(LEN(TRIM(E2))=8,"00"&TRIM(E2),"CHECK")) | AE2: =IFERROR(INDEX('8_3nf_customer'!$C:$C,MATCH(AD2,'8_3nf_customer'!$B:$B,0)),"NOT FOUND") | AF2: =IFERROR(INDEX('8_3nf_customer'!$D:$D,MATCH(AD2,'8_3nf_customer'!$B:$B,0)),"NOT FOUND") | AG2: =IF(ISNUMBER(AF2),DATEDIF(AF2,L2,"y"),"NOT FOUND") | AH2: =IFERROR(INDEX('8_3nf_customer'!$E:$E,MATCH(AD2,'8_3nf_customer'!$B:$B,0)),"NOT FOUND") | AI2: =IF(_xlfn.MAXIFS('9_3nf_customer_history'!$B$2:$B$500,'9_3nf_customer_history'!$A$2:$A$500,AD2,'9_3nf_customer_history'!$B$2:$B$500,"<="&L2)=0,"NOT FOUND",_xlfn.MAXIFS('9_3nf_customer_history'!$B$2:$B$500,'9_3nf_customer_history'!$A$2:$A$500,AD2,'9_3nf_customer_history'!$B$2:$B$500,"<="&L2)) | AJ2: =IF(AI2="NOT FOUND","NOT FOUND",INDEX('9_3nf_customer_history'!$C:$C,SUMPRODUCT(('9_3nf_customer_history'!$A$2:$A$500=AD2)*('9_3nf_customer_history'!$B$2:$B$500=AI2)*ROW('9_3nf_customer_history'!$A$2:$A$500)))) | AK2: =IF(AI2="NOT FOUND","NOT FOUND",INDEX('9_3nf_customer_history'!$D:$D,SUMPRODUCT(('9_3nf_customer_history'!$A$2:$A$500=AD2)*('9_3nf_customer_history'!$B$2:$B$500=AI2)*ROW('9_3nf_customer_history'!$A$2:$A$500)))) | AL2: =UPPER(TRIM(H2)) | AM2: =IF(_xlfn.MAXIFS('10_ref_fx_rate'!$B$2:$B$2000,'10_ref_fx_rate'!$A$2:$A$2000,AL2,'10_ref_fx_rate'!$B$2:$B$2000,"<="&L2)=0,"NOT FOUND",_xlfn.MAXIFS('10_ref_fx_rate'!$B$2:$B$2000,'10_ref_fx_rate'!$A$2:$A$2000,AL2,'10_ref_fx_rate'!$B$2:$B$2000,"<="&L2)) | AN2: =IF(AM2="NOT FOUND","NOT FOUND",SUMIFS('10_ref_fx_rate'!$D$2:$D$2000,'10_ref_fx_rate'!$A$2:$A$2000,AL2,'10_ref_fx_rate'!$B$2:$B$2000,AM2)) | AO2: =IF(ISNUMBER(AN2),I2*AN2,"NOT FOUND") | AP2: =UPPER(TRIM(J2)) | AQ2: =IF(AP2="","SELF-DIRECTED",IF(ISNUMBER(MATCH(AP2,'11_3nf_sales_person'!$A:$A,0)),IF(EXACT(AP2,J2),"OK","OK (auto-fixed)"),IF(ISNA(MATCH($A2,'12_sales_person_confirmation'!$A:$A,0)),"CONFIRM (not logged)",IF(INDEX('12_sales_person_confirmation'!$I:$I,MATCH($A2,'12_sales_person_confirmation'!$A:$A,0))="CONFIRMED","CONFIRMED ("&LOWER(INDEX('12_sales_person_confirmation'!$E:$E,MATCH($A2,'12_sales_person_confirmation'!$A:$A,0)))&")","PENDING CONFIRM")))) | AR2: =IF(OR(AQ2="OK",AQ2="OK (auto-fixed)"),AP2,IF(LEFT(AQ2,9)="CONFIRMED",INDEX('12_sales_person_confirmation'!$F:$F,MATCH($A2,'12_sales_person_confirmation'!$A:$A,0)),"")) | AS2: =IF(AR2="","",INDEX('11_3nf_sales_person'!$B:$B,MATCH(AR2,'11_3nf_sales_person'!$A:$A,0)))
A3: =IF(ISBLANK('1_raw_log'!A3),"",'1_raw_log'!A3) | B3: =IF(ISBLANK('1_raw_log'!B3),"",'1_raw_log'!B3) | C3: =IF(ISBLANK('1_raw_log'!C3),"",'1_raw_log'!C3) | D3: =IF(ISBLANK('1_raw_log'!D3),"",'1_raw_log'!D3) | E3: =IF(ISBLANK('1_raw_log'!E3),"",'1_raw_log'!E3) | F3: =IF(ISBLANK('1_raw_log'!F3),"",'1_raw_log'!F3) | G3: =IF(ISBLANK('1_raw_log'!G3),"",'1_raw_log'!G3) | H3: =IF(ISBLANK('1_raw_log'!H3),"",'1_raw_log'!H3) | ... K3: =IF(ISBLANK('1_raw_log'!K3),"",'1_raw_log'!K3) | L3: =INT(B3) | M3: =ROUND(MOD(B3,1)*1440,0)/1440 | N3: =IFERROR(INDEX('3_ref_date'!$B:$B,MATCH(L3,'3_ref_date'!$A:$A,0)),"NOT FOUND") | O3: =IFERROR(INDEX('3_ref_date'!$C:$C,MATCH(L3,'3_ref_date'!$A:$A,0)),"NOT FOUND") | P3: =IFERROR(INDEX('3_ref_date'!$D:$D,MATCH(L3,'3_ref_date'!$A:$A,0)),"NOT FOUND") | Q3: =IFERROR(INDEX('3_ref_date'!$E:$E,MATCH(L3,'3_ref_date'!$A:$A,0)),"NOT FOUND") | R3: =IFERROR(INDEX('3_ref_date'!$F:$F,MATCH(L3,'3_ref_date'!$A:$A,0)),"NOT FOUND") | S3: =IFERROR(INDEX('4_ref_time'!$D:$D,MATCH(ROUND(M3*1440,0),'4_ref_time'!$A:$A,0)),"NOT FOUND") | T3: =UPPER(TRIM(C3)) | U3: =IF(_xlfn.MAXIFS('6_3nf_branch_history'!$B$2:$B$50,'6_3nf_branch_history'!$A$2:$A$50,T3,'6_3nf_branch_history'!$B$2:$B$50,"<="&L3)=0,"NOT FOUND",_xlfn.MAXIFS('6_3nf_branch_history'!$B$2:$B$50,'6_3nf_branch_history'!$A$2:$A$50,T3,'6_3nf_branch_history'!$B$2:$B$50,"<="&L3)) | V3: =IF(U3="NOT FOUND","NOT FOUND",INDEX('6_3nf_branch_history'!$C:$C,SUMPRODUCT(('6_3nf_branch_history'!$A$2:$A$50=T3)*('6_3nf_branch_history'!$B$2:$B$50=U3)*ROW('6_3nf_branch_history'!$A$2:$A$50)))) | W3: =IF(U3="NOT FOUND","NOT FOUND",INDEX('6_3nf_branch_history'!$D:$D,SUMPRODUCT(('6_3nf_branch_history'!$A$2:$A$50=T3)*('6_3nf_branch_history'!$B$2:$B$50=U3)*ROW('6_3nf_branch_history'!$A$2:$A$50)))) | X3: =IF(U3="NOT FOUND","NOT FOUND",INDEX('6_3nf_branch_history'!$E:$E,SUMPRODUCT(('6_3nf_branch_history'!$A$2:$A$50=T3)*('6_3nf_branch_history'!$B$2:$B$50=U3)*ROW('6_3nf_branch_history'!$A$2:$A$50)))) | Y3: =UPPER(TRIM(D3)) | Z3: =IFERROR(INDEX('7_3nf_product'!$B:$B,MATCH(Y3,'7_3nf_product'!$A:$A,0)),"NOT FOUND") | AA3: =IFERROR(INDEX('7_3nf_product'!$C:$C,MATCH(Y3,'7_3nf_product'!$A:$A,0)),"NOT FOUND") | AB3: =IFERROR(INDEX('7_3nf_product'!$D:$D,MATCH(Y3,'7_3nf_product'!$A:$A,0)),"NOT FOUND") | AC3: =IFERROR(INDEX('7_3nf_product'!$E:$E,MATCH(Y3,'7_3nf_product'!$A:$A,0)),"NOT FOUND") | AD3: =IF(LEN(TRIM(E3))=10,TRIM(E3),IF(LEN(TRIM(E3))=8,"00"&TRIM(E3),"CHECK")) | AE3: =IFERROR(INDEX('8_3nf_customer'!$C:$C,MATCH(AD3,'8_3nf_customer'!$B:$B,0)),"NOT FOUND") | AF3: =IFERROR(INDEX('8_3nf_customer'!$D:$D,MATCH(AD3,'8_3nf_customer'!$B:$B,0)),"NOT FOUND") | AG3: =IF(ISNUMBER(AF3),DATEDIF(AF3,L3,"y"),"NOT FOUND") | AH3: =IFERROR(INDEX('8_3nf_customer'!$E:$E,MATCH(AD3,'8_3nf_customer'!$B:$B,0)),"NOT FOUND") | AI3: =IF(_xlfn.MAXIFS('9_3nf_customer_history'!$B$2:$B$500,'9_3nf_customer_history'!$A$2:$A$500,AD3,'9_3nf_customer_history'!$B$2:$B$500,"<="&L3)=0,"NOT FOUND",_xlfn.MAXIFS('9_3nf_customer_history'!$B$2:$B$500,'9_3nf_customer_history'!$A$2:$A$500,AD3,'9_3nf_customer_history'!$B$2:$B$500,"<="&L3)) | AJ3: =IF(AI3="NOT FOUND","NOT FOUND",INDEX('9_3nf_customer_history'!$C:$C,SUMPRODUCT(('9_3nf_customer_history'!$A$2:$A$500=AD3)*('9_3nf_customer_history'!$B$2:$B$500=AI3)*ROW('9_3nf_customer_history'!$A$2:$A$500)))) | AK3: =IF(AI3="NOT FOUND","NOT FOUND",INDEX('9_3nf_customer_history'!$D:$D,SUMPRODUCT(('9_3nf_customer_history'!$A$2:$A$500=AD3)*('9_3nf_customer_history'!$B$2:$B$500=AI3)*ROW('9_3nf_customer_history'!$A$2:$A$500)))) | AL3: =UPPER(TRIM(H3)) | AM3: =IF(_xlfn.MAXIFS('10_ref_fx_rate'!$B$2:$B$2000,'10_ref_fx_rate'!$A$2:$A$2000,AL3,'10_ref_fx_rate'!$B$2:$B$2000,"<="&L3)=0,"NOT FOUND",_xlfn.MAXIFS('10_ref_fx_rate'!$B$2:$B$2000,'10_ref_fx_rate'!$A$2:$A$2000,AL3,'10_ref_fx_rate'!$B$2:$B$2000,"<="&L3)) | AN3: =IF(AM3="NOT FOUND","NOT FOUND",SUMIFS('10_ref_fx_rate'!$D$2:$D$2000,'10_ref_fx_rate'!$A$2:$A$2000,AL3,'10_ref_fx_rate'!$B$2:$B$2000,AM3)) | AO3: =IF(ISNUMBER(AN3),I3*AN3,"NOT FOUND") | AP3: =UPPER(TRIM(J3)) | AQ3: =IF(AP3="","SELF-DIRECTED",IF(ISNUMBER(MATCH(AP3,'11_3nf_sales_person'!$A:$A,0)),IF(EXACT(AP3,J3),"OK","OK (auto-fixed)"),IF(ISNA(MATCH($A3,'12_sales_person_confirmation'!$A:$A,0)),"CONFIRM (not logged)",IF(INDEX('12_sales_person_confirmation'!$I:$I,MATCH($A3,'12_sales_person_confirmation'!$A:$A,0))="CONFIRMED","CONFIRMED ("&LOWER(INDEX('12_sales_person_confirmation'!$E:$E,MATCH($A3,'12_sales_person_confirmation'!$A:$A,0)))&")","PENDING CONFIRM")))) | AR3: =IF(OR(AQ3="OK",AQ3="OK (auto-fixed)"),AP3,IF(LEFT(AQ3,9)="CONFIRMED",INDEX('12_sales_person_confirmation'!$F:$F,MATCH($A3,'12_sales_person_confirmation'!$A:$A,0)),"")) | AS3: =IF(AR3="","",INDEX('11_3nf_sales_person'!$B:$B,MATCH(AR3,'11_3nf_sales_person'!$A:$A,0)))
A4: =IF(ISBLANK('1_raw_log'!A4),"",'1_raw_log'!A4) | B4: =IF(ISBLANK('1_raw_log'!B4),"",'1_raw_log'!B4) | C4: =IF(ISBLANK('1_raw_log'!C4),"",'1_raw_log'!C4) | D4: =IF(ISBLANK('1_raw_log'!D4),"",'1_raw_log'!D4) | E4: =IF(ISBLANK('1_raw_log'!E4),"",'1_raw_log'!E4) | F4: =IF(ISBLANK('1_raw_log'!F4),"",'1_raw_log'!F4) | G4: =IF(ISBLANK('1_raw_log'!G4),"",'1_raw_log'!G4) | H4: =IF(ISBLANK('1_raw_log'!H4),"",'1_raw_log'!H4) | ... K4: =IF(ISBLANK('1_raw_log'!K4),"",'1_raw_log'!K4) | L4: =INT(B4) | M4: =ROUND(MOD(B4,1)*1440,0)/1440 | N4: =IFERROR(INDEX('3_ref_date'!$B:$B,MATCH(L4,'3_ref_date'!$A:$A,0)),"NOT FOUND") | O4: =IFERROR(INDEX('3_ref_date'!$C:$C,MATCH(L4,'3_ref_date'!$A:$A,0)),"NOT FOUND") | P4: =IFERROR(INDEX('3_ref_date'!$D:$D,MATCH(L4,'3_ref_date'!$A:$A,0)),"NOT FOUND") | Q4: =IFERROR(INDEX('3_ref_date'!$E:$E,MATCH(L4,'3_ref_date'!$A:$A,0)),"NOT FOUND") | R4: =IFERROR(INDEX('3_ref_date'!$F:$F,MATCH(L4,'3_ref_date'!$A:$A,0)),"NOT FOUND") | S4: =IFERROR(INDEX('4_ref_time'!$D:$D,MATCH(ROUND(M4*1440,0),'4_ref_time'!$A:$A,0)),"NOT FOUND") | T4: =UPPER(TRIM(C4)) | U4: =IF(_xlfn.MAXIFS('6_3nf_branch_history'!$B$2:$B$50,'6_3nf_branch_history'!$A$2:$A$50,T4,'6_3nf_branch_history'!$B$2:$B$50,"<="&L4)=0,"NOT FOUND",_xlfn.MAXIFS('6_3nf_branch_history'!$B$2:$B$50,'6_3nf_branch_history'!$A$2:$A$50,T4,'6_3nf_branch_history'!$B$2:$B$50,"<="&L4)) | V4: =IF(U4="NOT FOUND","NOT FOUND",INDEX('6_3nf_branch_history'!$C:$C,SUMPRODUCT(('6_3nf_branch_history'!$A$2:$A$50=T4)*('6_3nf_branch_history'!$B$2:$B$50=U4)*ROW('6_3nf_branch_history'!$A$2:$A$50)))) | W4: =IF(U4="NOT FOUND","NOT FOUND",INDEX('6_3nf_branch_history'!$D:$D,SUMPRODUCT(('6_3nf_branch_history'!$A$2:$A$50=T4)*('6_3nf_branch_history'!$B$2:$B$50=U4)*ROW('6_3nf_branch_history'!$A$2:$A$50)))) | X4: =IF(U4="NOT FOUND","NOT FOUND",INDEX('6_3nf_branch_history'!$E:$E,SUMPRODUCT(('6_3nf_branch_history'!$A$2:$A$50=T4)*('6_3nf_branch_history'!$B$2:$B$50=U4)*ROW('6_3nf_branch_history'!$A$2:$A$50)))) | Y4: =UPPER(TRIM(D4)) | Z4: =IFERROR(INDEX('7_3nf_product'!$B:$B,MATCH(Y4,'7_3nf_product'!$A:$A,0)),"NOT FOUND") | AA4: =IFERROR(INDEX('7_3nf_product'!$C:$C,MATCH(Y4,'7_3nf_product'!$A:$A,0)),"NOT FOUND") | AB4: =IFERROR(INDEX('7_3nf_product'!$D:$D,MATCH(Y4,'7_3nf_product'!$A:$A,0)),"NOT FOUND") | AC4: =IFERROR(INDEX('7_3nf_product'!$E:$E,MATCH(Y4,'7_3nf_product'!$A:$A,0)),"NOT FOUND") | AD4: =IF(LEN(TRIM(E4))=10,TRIM(E4),IF(LEN(TRIM(E4))=8,"00"&TRIM(E4),"CHECK")) | AE4: =IFERROR(INDEX('8_3nf_customer'!$C:$C,MATCH(AD4,'8_3nf_customer'!$B:$B,0)),"NOT FOUND") | AF4: =IFERROR(INDEX('8_3nf_customer'!$D:$D,MATCH(AD4,'8_3nf_customer'!$B:$B,0)),"NOT FOUND") | AG4: =IF(ISNUMBER(AF4),DATEDIF(AF4,L4,"y"),"NOT FOUND") | AH4: =IFERROR(INDEX('8_3nf_customer'!$E:$E,MATCH(AD4,'8_3nf_customer'!$B:$B,0)),"NOT FOUND") | AI4: =IF(_xlfn.MAXIFS('9_3nf_customer_history'!$B$2:$B$500,'9_3nf_customer_history'!$A$2:$A$500,AD4,'9_3nf_customer_history'!$B$2:$B$500,"<="&L4)=0,"NOT FOUND",_xlfn.MAXIFS('9_3nf_customer_history'!$B$2:$B$500,'9_3nf_customer_history'!$A$2:$A$500,AD4,'9_3nf_customer_history'!$B$2:$B$500,"<="&L4)) | AJ4: =IF(AI4="NOT FOUND","NOT FOUND",INDEX('9_3nf_customer_history'!$C:$C,SUMPRODUCT(('9_3nf_customer_history'!$A$2:$A$500=AD4)*('9_3nf_customer_history'!$B$2:$B$500=AI4)*ROW('9_3nf_customer_history'!$A$2:$A$500)))) | AK4: =IF(AI4="NOT FOUND","NOT FOUND",INDEX('9_3nf_customer_history'!$D:$D,SUMPRODUCT(('9_3nf_customer_history'!$A$2:$A$500=AD4)*('9_3nf_customer_history'!$B$2:$B$500=AI4)*ROW('9_3nf_customer_history'!$A$2:$A$500)))) | AL4: =UPPER(TRIM(H4)) | AM4: =IF(_xlfn.MAXIFS('10_ref_fx_rate'!$B$2:$B$2000,'10_ref_fx_rate'!$A$2:$A$2000,AL4,'10_ref_fx_rate'!$B$2:$B$2000,"<="&L4)=0,"NOT FOUND",_xlfn.MAXIFS('10_ref_fx_rate'!$B$2:$B$2000,'10_ref_fx_rate'!$A$2:$A$2000,AL4,'10_ref_fx_rate'!$B$2:$B$2000,"<="&L4)) | AN4: =IF(AM4="NOT FOUND","NOT FOUND",SUMIFS('10_ref_fx_rate'!$D$2:$D$2000,'10_ref_fx_rate'!$A$2:$A$2000,AL4,'10_ref_fx_rate'!$B$2:$B$2000,AM4)) | AO4: =IF(ISNUMBER(AN4),I4*AN4,"NOT FOUND") | AP4: =UPPER(TRIM(J4)) | AQ4: =IF(AP4="","SELF-DIRECTED",IF(ISNUMBER(MATCH(AP4,'11_3nf_sales_person'!$A:$A,0)),IF(EXACT(AP4,J4),"OK","OK (auto-fixed)"),IF(ISNA(MATCH($A4,'12_sales_person_confirmation'!$A:$A,0)),"CONFIRM (not logged)",IF(INDEX('12_sales_person_confirmation'!$I:$I,MATCH($A4,'12_sales_person_confirmation'!$A:$A,0))="CONFIRMED","CONFIRMED ("&LOWER(INDEX('12_sales_person_confirmation'!$E:$E,MATCH($A4,'12_sales_person_confirmation'!$A:$A,0)))&")","PENDING CONFIRM")))) | AR4: =IF(OR(AQ4="OK",AQ4="OK (auto-fixed)"),AP4,IF(LEFT(AQ4,9)="CONFIRMED",INDEX('12_sales_person_confirmation'!$F:$F,MATCH($A4,'12_sales_person_confirmation'!$A:$A,0)),"")) | AS4: =IF(AR4="","",INDEX('11_3nf_sales_person'!$B:$B,MATCH(AR4,'11_3nf_sales_person'!$A:$A,0)))
A5: =IF(ISBLANK('1_raw_log'!A5),"",'1_raw_log'!A5) | B5: =IF(ISBLANK('1_raw_log'!B5),"",'1_raw_log'!B5) | C5: =IF(ISBLANK('1_raw_log'!C5),"",'1_raw_log'!C5) | D5: =IF(ISBLANK('1_raw_log'!D5),"",'1_raw_log'!D5) | E5: =IF(ISBLANK('1_raw_log'!E5),"",'1_raw_log'!E5) | F5: =IF(ISBLANK('1_raw_log'!F5),"",'1_raw_log'!F5) | G5: =IF(ISBLANK('1_raw_log'!G5),"",'1_raw_log'!G5) | H5: =IF(ISBLANK('1_raw_log'!H5),"",'1_raw_log'!H5) | ... K5: =IF(ISBLANK('1_raw_log'!K5),"",'1_raw_log'!K5) | L5: =INT(B5) | M5: =ROUND(MOD(B5,1)*1440,0)/1440 | N5: =IFERROR(INDEX('3_ref_date'!$B:$B,MATCH(L5,'3_ref_date'!$A:$A,0)),"NOT FOUND") | O5: =IFERROR(INDEX('3_ref_date'!$C:$C,MATCH(L5,'3_ref_date'!$A:$A,0)),"NOT FOUND") | P5: =IFERROR(INDEX('3_ref_date'!$D:$D,MATCH(L5,'3_ref_date'!$A:$A,0)),"NOT FOUND") | Q5: =IFERROR(INDEX('3_ref_date'!$E:$E,MATCH(L5,'3_ref_date'!$A:$A,0)),"NOT FOUND") | R5: =IFERROR(INDEX('3_ref_date'!$F:$F,MATCH(L5,'3_ref_date'!$A:$A,0)),"NOT FOUND") | S5: =IFERROR(INDEX('4_ref_time'!$D:$D,MATCH(ROUND(M5*1440,0),'4_ref_time'!$A:$A,0)),"NOT FOUND") | T5: =UPPER(TRIM(C5)) | U5: =IF(_xlfn.MAXIFS('6_3nf_branch_history'!$B$2:$B$50,'6_3nf_branch_history'!$A$2:$A$50,T5,'6_3nf_branch_history'!$B$2:$B$50,"<="&L5)=0,"NOT FOUND",_xlfn.MAXIFS('6_3nf_branch_history'!$B$2:$B$50,'6_3nf_branch_history'!$A$2:$A$50,T5,'6_3nf_branch_history'!$B$2:$B$50,"<="&L5)) | V5: =IF(U5="NOT FOUND","NOT FOUND",INDEX('6_3nf_branch_history'!$C:$C,SUMPRODUCT(('6_3nf_branch_history'!$A$2:$A$50=T5)*('6_3nf_branch_history'!$B$2:$B$50=U5)*ROW('6_3nf_branch_history'!$A$2:$A$50)))) | W5: =IF(U5="NOT FOUND","NOT FOUND",INDEX('6_3nf_branch_history'!$D:$D,SUMPRODUCT(('6_3nf_branch_history'!$A$2:$A$50=T5)*('6_3nf_branch_history'!$B$2:$B$50=U5)*ROW('6_3nf_branch_history'!$A$2:$A$50)))) | X5: =IF(U5="NOT FOUND","NOT FOUND",INDEX('6_3nf_branch_history'!$E:$E,SUMPRODUCT(('6_3nf_branch_history'!$A$2:$A$50=T5)*('6_3nf_branch_history'!$B$2:$B$50=U5)*ROW('6_3nf_branch_history'!$A$2:$A$50)))) | Y5: =UPPER(TRIM(D5)) | Z5: =IFERROR(INDEX('7_3nf_product'!$B:$B,MATCH(Y5,'7_3nf_product'!$A:$A,0)),"NOT FOUND") | AA5: =IFERROR(INDEX('7_3nf_product'!$C:$C,MATCH(Y5,'7_3nf_product'!$A:$A,0)),"NOT FOUND") | AB5: =IFERROR(INDEX('7_3nf_product'!$D:$D,MATCH(Y5,'7_3nf_product'!$A:$A,0)),"NOT FOUND") | AC5: =IFERROR(INDEX('7_3nf_product'!$E:$E,MATCH(Y5,'7_3nf_product'!$A:$A,0)),"NOT FOUND") | AD5: =IF(LEN(TRIM(E5))=10,TRIM(E5),IF(LEN(TRIM(E5))=8,"00"&TRIM(E5),"CHECK")) | AE5: =IFERROR(INDEX('8_3nf_customer'!$C:$C,MATCH(AD5,'8_3nf_customer'!$B:$B,0)),"NOT FOUND") | AF5: =IFERROR(INDEX('8_3nf_customer'!$D:$D,MATCH(AD5,'8_3nf_customer'!$B:$B,0)),"NOT FOUND") | AG5: =IF(ISNUMBER(AF5),DATEDIF(AF5,L5,"y"),"NOT FOUND") | AH5: =IFERROR(INDEX('8_3nf_customer'!$E:$E,MATCH(AD5,'8_3nf_customer'!$B:$B,0)),"NOT FOUND") | AI5: =IF(_xlfn.MAXIFS('9_3nf_customer_history'!$B$2:$B$500,'9_3nf_customer_history'!$A$2:$A$500,AD5,'9_3nf_customer_history'!$B$2:$B$500,"<="&L5)=0,"NOT FOUND",_xlfn.MAXIFS('9_3nf_customer_history'!$B$2:$B$500,'9_3nf_customer_history'!$A$2:$A$500,AD5,'9_3nf_customer_history'!$B$2:$B$500,"<="&L5)) | AJ5: =IF(AI5="NOT FOUND","NOT FOUND",INDEX('9_3nf_customer_history'!$C:$C,SUMPRODUCT(('9_3nf_customer_history'!$A$2:$A$500=AD5)*('9_3nf_customer_history'!$B$2:$B$500=AI5)*ROW('9_3nf_customer_history'!$A$2:$A$500)))) | AK5: =IF(AI5="NOT FOUND","NOT FOUND",INDEX('9_3nf_customer_history'!$D:$D,SUMPRODUCT(('9_3nf_customer_history'!$A$2:$A$500=AD5)*('9_3nf_customer_history'!$B$2:$B$500=AI5)*ROW('9_3nf_customer_history'!$A$2:$A$500)))) | AL5: =UPPER(TRIM(H5)) | AM5: =IF(_xlfn.MAXIFS('10_ref_fx_rate'!$B$2:$B$2000,'10_ref_fx_rate'!$A$2:$A$2000,AL5,'10_ref_fx_rate'!$B$2:$B$2000,"<="&L5)=0,"NOT FOUND",_xlfn.MAXIFS('10_ref_fx_rate'!$B$2:$B$2000,'10_ref_fx_rate'!$A$2:$A$2000,AL5,'10_ref_fx_rate'!$B$2:$B$2000,"<="&L5)) | AN5: =IF(AM5="NOT FOUND","NOT FOUND",SUMIFS('10_ref_fx_rate'!$D$2:$D$2000,'10_ref_fx_rate'!$A$2:$A$2000,AL5,'10_ref_fx_rate'!$B$2:$B$2000,AM5)) | AO5: =IF(ISNUMBER(AN5),I5*AN5,"NOT FOUND") | AP5: =UPPER(TRIM(J5)) | AQ5: =IF(AP5="","SELF-DIRECTED",IF(ISNUMBER(MATCH(AP5,'11_3nf_sales_person'!$A:$A,0)),IF(EXACT(AP5,J5),"OK","OK (auto-fixed)"),IF(ISNA(MATCH($A5,'12_sales_person_confirmation'!$A:$A,0)),"CONFIRM (not logged)",IF(INDEX('12_sales_person_confirmation'!$I:$I,MATCH($A5,'12_sales_person_confirmation'!$A:$A,0))="CONFIRMED","CONFIRMED ("&LOWER(INDEX('12_sales_person_confirmation'!$E:$E,MATCH($A5,'12_sales_person_confirmation'!$A:$A,0)))&")","PENDING CONFIRM")))) | AR5: =IF(OR(AQ5="OK",AQ5="OK (auto-fixed)"),AP5,IF(LEFT(AQ5,9)="CONFIRMED",INDEX('12_sales_person_confirmation'!$F:$F,MATCH($A5,'12_sales_person_confirmation'!$A:$A,0)),"")) | AS5: =IF(AR5="","",INDEX('11_3nf_sales_person'!$B:$B,MATCH(AR5,'11_3nf_sales_person'!$A:$A,0)))
A6: =IF(ISBLANK('1_raw_log'!A6),"",'1_raw_log'!A6) | B6: =IF(ISBLANK('1_raw_log'!B6),"",'1_raw_log'!B6) | C6: =IF(ISBLANK('1_raw_log'!C6),"",'1_raw_log'!C6) | D6: =IF(ISBLANK('1_raw_log'!D6),"",'1_raw_log'!D6) | E6: =IF(ISBLANK('1_raw_log'!E6),"",'1_raw_log'!E6) | F6: =IF(ISBLANK('1_raw_log'!F6),"",'1_raw_log'!F6) | G6: =IF(ISBLANK('1_raw_log'!G6),"",'1_raw_log'!G6) | H6: =IF(ISBLANK('1_raw_log'!H6),"",'1_raw_log'!H6) | ... K6: =IF(ISBLANK('1_raw_log'!K6),"",'1_raw_log'!K6) | L6: =INT(B6) | M6: =ROUND(MOD(B6,1)*1440,0)/1440 | N6: =IFERROR(INDEX('3_ref_date'!$B:$B,MATCH(L6,'3_ref_date'!$A:$A,0)),"NOT FOUND") | O6: =IFERROR(INDEX('3_ref_date'!$C:$C,MATCH(L6,'3_ref_date'!$A:$A,0)),"NOT FOUND") | P6: =IFERROR(INDEX('3_ref_date'!$D:$D,MATCH(L6,'3_ref_date'!$A:$A,0)),"NOT FOUND") | Q6: =IFERROR(INDEX('3_ref_date'!$E:$E,MATCH(L6,'3_ref_date'!$A:$A,0)),"NOT FOUND") | R6: =IFERROR(INDEX('3_ref_date'!$F:$F,MATCH(L6,'3_ref_date'!$A:$A,0)),"NOT FOUND") | S6: =IFERROR(INDEX('4_ref_time'!$D:$D,MATCH(ROUND(M6*1440,0),'4_ref_time'!$A:$A,0)),"NOT FOUND") | T6: =UPPER(TRIM(C6)) | U6: =IF(_xlfn.MAXIFS('6_3nf_branch_history'!$B$2:$B$50,'6_3nf_branch_history'!$A$2:$A$50,T6,'6_3nf_branch_history'!$B$2:$B$50,"<="&L6)=0,"NOT FOUND",_xlfn.MAXIFS('6_3nf_branch_history'!$B$2:$B$50,'6_3nf_branch_history'!$A$2:$A$50,T6,'6_3nf_branch_history'!$B$2:$B$50,"<="&L6)) | V6: =IF(U6="NOT FOUND","NOT FOUND",INDEX('6_3nf_branch_history'!$C:$C,SUMPRODUCT(('6_3nf_branch_history'!$A$2:$A$50=T6)*('6_3nf_branch_history'!$B$2:$B$50=U6)*ROW('6_3nf_branch_history'!$A$2:$A$50)))) | W6: =IF(U6="NOT FOUND","NOT FOUND",INDEX('6_3nf_branch_history'!$D:$D,SUMPRODUCT(('6_3nf_branch_history'!$A$2:$A$50=T6)*('6_3nf_branch_history'!$B$2:$B$50=U6)*ROW('6_3nf_branch_history'!$A$2:$A$50)))) | X6: =IF(U6="NOT FOUND","NOT FOUND",INDEX('6_3nf_branch_history'!$E:$E,SUMPRODUCT(('6_3nf_branch_history'!$A$2:$A$50=T6)*('6_3nf_branch_history'!$B$2:$B$50=U6)*ROW('6_3nf_branch_history'!$A$2:$A$50)))) | Y6: =UPPER(TRIM(D6)) | Z6: =IFERROR(INDEX('7_3nf_product'!$B:$B,MATCH(Y6,'7_3nf_product'!$A:$A,0)),"NOT FOUND") | AA6: =IFERROR(INDEX('7_3nf_product'!$C:$C,MATCH(Y6,'7_3nf_product'!$A:$A,0)),"NOT FOUND") | AB6: =IFERROR(INDEX('7_3nf_product'!$D:$D,MATCH(Y6,'7_3nf_product'!$A:$A,0)),"NOT FOUND") | AC6: =IFERROR(INDEX('7_3nf_product'!$E:$E,MATCH(Y6,'7_3nf_product'!$A:$A,0)),"NOT FOUND") | AD6: =IF(LEN(TRIM(E6))=10,TRIM(E6),IF(LEN(TRIM(E6))=8,"00"&TRIM(E6),"CHECK")) | AE6: =IFERROR(INDEX('8_3nf_customer'!$C:$C,MATCH(AD6,'8_3nf_customer'!$B:$B,0)),"NOT FOUND") | AF6: =IFERROR(INDEX('8_3nf_customer'!$D:$D,MATCH(AD6,'8_3nf_customer'!$B:$B,0)),"NOT FOUND") | AG6: =IF(ISNUMBER(AF6),DATEDIF(AF6,L6,"y"),"NOT FOUND") | AH6: =IFERROR(INDEX('8_3nf_customer'!$E:$E,MATCH(AD6,'8_3nf_customer'!$B:$B,0)),"NOT FOUND") | AI6: =IF(_xlfn.MAXIFS('9_3nf_customer_history'!$B$2:$B$500,'9_3nf_customer_history'!$A$2:$A$500,AD6,'9_3nf_customer_history'!$B$2:$B$500,"<="&L6)=0,"NOT FOUND",_xlfn.MAXIFS('9_3nf_customer_history'!$B$2:$B$500,'9_3nf_customer_history'!$A$2:$A$500,AD6,'9_3nf_customer_history'!$B$2:$B$500,"<="&L6)) | AJ6: =IF(AI6="NOT FOUND","NOT FOUND",INDEX('9_3nf_customer_history'!$C:$C,SUMPRODUCT(('9_3nf_customer_history'!$A$2:$A$500=AD6)*('9_3nf_customer_history'!$B$2:$B$500=AI6)*ROW('9_3nf_customer_history'!$A$2:$A$500)))) | AK6: =IF(AI6="NOT FOUND","NOT FOUND",INDEX('9_3nf_customer_history'!$D:$D,SUMPRODUCT(('9_3nf_customer_history'!$A$2:$A$500=AD6)*('9_3nf_customer_history'!$B$2:$B$500=AI6)*ROW('9_3nf_customer_history'!$A$2:$A$500)))) | AL6: =UPPER(TRIM(H6)) | AM6: =IF(_xlfn.MAXIFS('10_ref_fx_rate'!$B$2:$B$2000,'10_ref_fx_rate'!$A$2:$A$2000,AL6,'10_ref_fx_rate'!$B$2:$B$2000,"<="&L6)=0,"NOT FOUND",_xlfn.MAXIFS('10_ref_fx_rate'!$B$2:$B$2000,'10_ref_fx_rate'!$A$2:$A$2000,AL6,'10_ref_fx_rate'!$B$2:$B$2000,"<="&L6)) | AN6: =IF(AM6="NOT FOUND","NOT FOUND",SUMIFS('10_ref_fx_rate'!$D$2:$D$2000,'10_ref_fx_rate'!$A$2:$A$2000,AL6,'10_ref_fx_rate'!$B$2:$B$2000,AM6)) | AO6: =IF(ISNUMBER(AN6),I6*AN6,"NOT FOUND") | AP6: =UPPER(TRIM(J6)) | AQ6: =IF(AP6="","SELF-DIRECTED",IF(ISNUMBER(MATCH(AP6,'11_3nf_sales_person'!$A:$A,0)),IF(EXACT(AP6,J6),"OK","OK (auto-fixed)"),IF(ISNA(MATCH($A6,'12_sales_person_confirmation'!$A:$A,0)),"CONFIRM (not logged)",IF(INDEX('12_sales_person_confirmation'!$I:$I,MATCH($A6,'12_sales_person_confirmation'!$A:$A,0))="CONFIRMED","CONFIRMED ("&LOWER(INDEX('12_sales_person_confirmation'!$E:$E,MATCH($A6,'12_sales_person_confirmation'!$A:$A,0)))&")","PENDING CONFIRM")))) | AR6: =IF(OR(AQ6="OK",AQ6="OK (auto-fixed)"),AP6,IF(LEFT(AQ6,9)="CONFIRMED",INDEX('12_sales_person_confirmation'!$F:$F,MATCH($A6,'12_sales_person_confirmation'!$A:$A,0)),"")) | AS6: =IF(AR6="","",INDEX('11_3nf_sales_person'!$B:$B,MATCH(AR6,'11_3nf_sales_person'!$A:$A,0)))
A7: =IF(ISBLANK('1_raw_log'!A7),"",'1_raw_log'!A7) | B7: =IF(ISBLANK('1_raw_log'!B7),"",'1_raw_log'!B7) | C7: =IF(ISBLANK('1_raw_log'!C7),"",'1_raw_log'!C7) | D7: =IF(ISBLANK('1_raw_log'!D7),"",'1_raw_log'!D7) | E7: =IF(ISBLANK('1_raw_log'!E7),"",'1_raw_log'!E7) | F7: =IF(ISBLANK('1_raw_log'!F7),"",'1_raw_log'!F7) | G7: =IF(ISBLANK('1_raw_log'!G7),"",'1_raw_log'!G7) | H7: =IF(ISBLANK('1_raw_log'!H7),"",'1_raw_log'!H7) | ... K7: =IF(ISBLANK('1_raw_log'!K7),"",'1_raw_log'!K7) | L7: =INT(B7) | M7: =ROUND(MOD(B7,1)*1440,0)/1440 | N7: =IFERROR(INDEX('3_ref_date'!$B:$B,MATCH(L7,'3_ref_date'!$A:$A,0)),"NOT FOUND") | O7: =IFERROR(INDEX('3_ref_date'!$C:$C,MATCH(L7,'3_ref_date'!$A:$A,0)),"NOT FOUND") | P7: =IFERROR(INDEX('3_ref_date'!$D:$D,MATCH(L7,'3_ref_date'!$A:$A,0)),"NOT FOUND") | Q7: =IFERROR(INDEX('3_ref_date'!$E:$E,MATCH(L7,'3_ref_date'!$A:$A,0)),"NOT FOUND") | R7: =IFERROR(INDEX('3_ref_date'!$F:$F,MATCH(L7,'3_ref_date'!$A:$A,0)),"NOT FOUND") | S7: =IFERROR(INDEX('4_ref_time'!$D:$D,MATCH(ROUND(M7*1440,0),'4_ref_time'!$A:$A,0)),"NOT FOUND") | T7: =UPPER(TRIM(C7)) | U7: =IF(_xlfn.MAXIFS('6_3nf_branch_history'!$B$2:$B$50,'6_3nf_branch_history'!$A$2:$A$50,T7,'6_3nf_branch_history'!$B$2:$B$50,"<="&L7)=0,"NOT FOUND",_xlfn.MAXIFS('6_3nf_branch_history'!$B$2:$B$50,'6_3nf_branch_history'!$A$2:$A$50,T7,'6_3nf_branch_history'!$B$2:$B$50,"<="&L7)) | V7: =IF(U7="NOT FOUND","NOT FOUND",INDEX('6_3nf_branch_history'!$C:$C,SUMPRODUCT(('6_3nf_branch_history'!$A$2:$A$50=T7)*('6_3nf_branch_history'!$B$2:$B$50=U7)*ROW('6_3nf_branch_history'!$A$2:$A$50)))) | W7: =IF(U7="NOT FOUND","NOT FOUND",INDEX('6_3nf_branch_history'!$D:$D,SUMPRODUCT(('6_3nf_branch_history'!$A$2:$A$50=T7)*('6_3nf_branch_history'!$B$2:$B$50=U7)*ROW('6_3nf_branch_history'!$A$2:$A$50)))) | X7: =IF(U7="NOT FOUND","NOT FOUND",INDEX('6_3nf_branch_history'!$E:$E,SUMPRODUCT(('6_3nf_branch_history'!$A$2:$A$50=T7)*('6_3nf_branch_history'!$B$2:$B$50=U7)*ROW('6_3nf_branch_history'!$A$2:$A$50)))) | Y7: =UPPER(TRIM(D7)) | Z7: =IFERROR(INDEX('7_3nf_product'!$B:$B,MATCH(Y7,'7_3nf_product'!$A:$A,0)),"NOT FOUND") | AA7: =IFERROR(INDEX('7_3nf_product'!$C:$C,MATCH(Y7,'7_3nf_product'!$A:$A,0)),"NOT FOUND") | AB7: =IFERROR(INDEX('7_3nf_product'!$D:$D,MATCH(Y7,'7_3nf_product'!$A:$A,0)),"NOT FOUND") | AC7: =IFERROR(INDEX('7_3nf_product'!$E:$E,MATCH(Y7,'7_3nf_product'!$A:$A,0)),"NOT FOUND") | AD7: =IF(LEN(TRIM(E7))=10,TRIM(E7),IF(LEN(TRIM(E7))=8,"00"&TRIM(E7),"CHECK")) | AE7: =IFERROR(INDEX('8_3nf_customer'!$C:$C,MATCH(AD7,'8_3nf_customer'!$B:$B,0)),"NOT FOUND") | AF7: =IFERROR(INDEX('8_3nf_customer'!$D:$D,MATCH(AD7,'8_3nf_customer'!$B:$B,0)),"NOT FOUND") | AG7: =IF(ISNUMBER(AF7),DATEDIF(AF7,L7,"y"),"NOT FOUND") | AH7: =IFERROR(INDEX('8_3nf_customer'!$E:$E,MATCH(AD7,'8_3nf_customer'!$B:$B,0)),"NOT FOUND") | AI7: =IF(_xlfn.MAXIFS('9_3nf_customer_history'!$B$2:$B$500,'9_3nf_customer_history'!$A$2:$A$500,AD7,'9_3nf_customer_history'!$B$2:$B$500,"<="&L7)=0,"NOT FOUND",_xlfn.MAXIFS('9_3nf_customer_history'!$B$2:$B$500,'9_3nf_customer_history'!$A$2:$A$500,AD7,'9_3nf_customer_history'!$B$2:$B$500,"<="&L7)) | AJ7: =IF(AI7="NOT FOUND","NOT FOUND",INDEX('9_3nf_customer_history'!$C:$C,SUMPRODUCT(('9_3nf_customer_history'!$A$2:$A$500=AD7)*('9_3nf_customer_history'!$B$2:$B$500=AI7)*ROW('9_3nf_customer_history'!$A$2:$A$500)))) | AK7: =IF(AI7="NOT FOUND","NOT FOUND",INDEX('9_3nf_customer_history'!$D:$D,SUMPRODUCT(('9_3nf_customer_history'!$A$2:$A$500=AD7)*('9_3nf_customer_history'!$B$2:$B$500=AI7)*ROW('9_3nf_customer_history'!$A$2:$A$500)))) | AL7: =UPPER(TRIM(H7)) | AM7: =IF(_xlfn.MAXIFS('10_ref_fx_rate'!$B$2:$B$2000,'10_ref_fx_rate'!$A$2:$A$2000,AL7,'10_ref_fx_rate'!$B$2:$B$2000,"<="&L7)=0,"NOT FOUND",_xlfn.MAXIFS('10_ref_fx_rate'!$B$2:$B$2000,'10_ref_fx_rate'!$A$2:$A$2000,AL7,'10_ref_fx_rate'!$B$2:$B$2000,"<="&L7)) | AN7: =IF(AM7="NOT FOUND","NOT FOUND",SUMIFS('10_ref_fx_rate'!$D$2:$D$2000,'10_ref_fx_rate'!$A$2:$A$2000,AL7,'10_ref_fx_rate'!$B$2:$B$2000,AM7)) | AO7: =IF(ISNUMBER(AN7),I7*AN7,"NOT FOUND") | AP7: =UPPER(TRIM(J7)) | AQ7: =IF(AP7="","SELF-DIRECTED",IF(ISNUMBER(MATCH(AP7,'11_3nf_sales_person'!$A:$A,0)),IF(EXACT(AP7,J7),"OK","OK (auto-fixed)"),IF(ISNA(MATCH($A7,'12_sales_person_confirmation'!$A:$A,0)),"CONFIRM (not logged)",IF(INDEX('12_sales_person_confirmation'!$I:$I,MATCH($A7,'12_sales_person_confirmation'!$A:$A,0))="CONFIRMED","CONFIRMED ("&LOWER(INDEX('12_sales_person_confirmation'!$E:$E,MATCH($A7,'12_sales_person_confirmation'!$A:$A,0)))&")","PENDING CONFIRM")))) | AR7: =IF(OR(AQ7="OK",AQ7="OK (auto-fixed)"),AP7,IF(LEFT(AQ7,9)="CONFIRMED",INDEX('12_sales_person_confirmation'!$F:$F,MATCH($A7,'12_sales_person_confirmation'!$A:$A,0)),"")) | AS7: =IF(AR7="","",INDEX('11_3nf_sales_person'!$B:$B,MATCH(AR7,'11_3nf_sales_person'!$A:$A,0)))
A8: =IF(ISBLANK('1_raw_log'!A8),"",'1_raw_log'!A8) | B8: =IF(ISBLANK('1_raw_log'!B8),"",'1_raw_log'!B8) | C8: =IF(ISBLANK('1_raw_log'!C8),"",'1_raw_log'!C8) | D8: =IF(ISBLANK('1_raw_log'!D8),"",'1_raw_log'!D8) | E8: =IF(ISBLANK('1_raw_log'!E8),"",'1_raw_log'!E8) | F8: =IF(ISBLANK('1_raw_log'!F8),"",'1_raw_log'!F8) | G8: =IF(ISBLANK('1_raw_log'!G8),"",'1_raw_log'!G8) | H8: =IF(ISBLANK('1_raw_log'!H8),"",'1_raw_log'!H8) | ... K8: =IF(ISBLANK('1_raw_log'!K8),"",'1_raw_log'!K8) | L8: =INT(B8) | M8: =ROUND(MOD(B8,1)*1440,0)/1440 | N8: =IFERROR(INDEX('3_ref_date'!$B:$B,MATCH(L8,'3_ref_date'!$A:$A,0)),"NOT FOUND") | O8: =IFERROR(INDEX('3_ref_date'!$C:$C,MATCH(L8,'3_ref_date'!$A:$A,0)),"NOT FOUND") | P8: =IFERROR(INDEX('3_ref_date'!$D:$D,MATCH(L8,'3_ref_date'!$A:$A,0)),"NOT FOUND") | Q8: =IFERROR(INDEX('3_ref_date'!$E:$E,MATCH(L8,'3_ref_date'!$A:$A,0)),"NOT FOUND") | R8: =IFERROR(INDEX('3_ref_date'!$F:$F,MATCH(L8,'3_ref_date'!$A:$A,0)),"NOT FOUND") | S8: =IFERROR(INDEX('4_ref_time'!$D:$D,MATCH(ROUND(M8*1440,0),'4_ref_time'!$A:$A,0)),"NOT FOUND") | T8: =UPPER(TRIM(C8)) | U8: =IF(_xlfn.MAXIFS('6_3nf_branch_history'!$B$2:$B$50,'6_3nf_branch_history'!$A$2:$A$50,T8,'6_3nf_branch_history'!$B$2:$B$50,"<="&L8)=0,"NOT FOUND",_xlfn.MAXIFS('6_3nf_branch_history'!$B$2:$B$50,'6_3nf_branch_history'!$A$2:$A$50,T8,'6_3nf_branch_history'!$B$2:$B$50,"<="&L8)) | V8: =IF(U8="NOT FOUND","NOT FOUND",INDEX('6_3nf_branch_history'!$C:$C,SUMPRODUCT(('6_3nf_branch_history'!$A$2:$A$50=T8)*('6_3nf_branch_history'!$B$2:$B$50=U8)*ROW('6_3nf_branch_history'!$A$2:$A$50)))) | W8: =IF(U8="NOT FOUND","NOT FOUND",INDEX('6_3nf_branch_history'!$D:$D,SUMPRODUCT(('6_3nf_branch_history'!$A$2:$A$50=T8)*('6_3nf_branch_history'!$B$2:$B$50=U8)*ROW('6_3nf_branch_history'!$A$2:$A$50)))) | X8: =IF(U8="NOT FOUND","NOT FOUND",INDEX('6_3nf_branch_history'!$E:$E,SUMPRODUCT(('6_3nf_branch_history'!$A$2:$A$50=T8)*('6_3nf_branch_history'!$B$2:$B$50=U8)*ROW('6_3nf_branch_history'!$A$2:$A$50)))) | Y8: =UPPER(TRIM(D8)) | Z8: =IFERROR(INDEX('7_3nf_product'!$B:$B,MATCH(Y8,'7_3nf_product'!$A:$A,0)),"NOT FOUND") | AA8: =IFERROR(INDEX('7_3nf_product'!$C:$C,MATCH(Y8,'7_3nf_product'!$A:$A,0)),"NOT FOUND") | AB8: =IFERROR(INDEX('7_3nf_product'!$D:$D,MATCH(Y8,'7_3nf_product'!$A:$A,0)),"NOT FOUND") | AC8: =IFERROR(INDEX('7_3nf_product'!$E:$E,MATCH(Y8,'7_3nf_product'!$A:$A,0)),"NOT FOUND") | AD8: =IF(LEN(TRIM(E8))=10,TRIM(E8),IF(LEN(TRIM(E8))=8,"00"&TRIM(E8),"CHECK")) | AE8: =IFERROR(INDEX('8_3nf_customer'!$C:$C,MATCH(AD8,'8_3nf_customer'!$B:$B,0)),"NOT FOUND") | AF8: =IFERROR(INDEX('8_3nf_customer'!$D:$D,MATCH(AD8,'8_3nf_customer'!$B:$B,0)),"NOT FOUND") | AG8: =IF(ISNUMBER(AF8),DATEDIF(AF8,L8,"y"),"NOT FOUND") | AH8: =IFERROR(INDEX('8_3nf_customer'!$E:$E,MATCH(AD8,'8_3nf_customer'!$B:$B,0)),"NOT FOUND") | AI8: =IF(_xlfn.MAXIFS('9_3nf_customer_history'!$B$2:$B$500,'9_3nf_customer_history'!$A$2:$A$500,AD8,'9_3nf_customer_history'!$B$2:$B$500,"<="&L8)=0,"NOT FOUND",_xlfn.MAXIFS('9_3nf_customer_history'!$B$2:$B$500,'9_3nf_customer_history'!$A$2:$A$500,AD8,'9_3nf_customer_history'!$B$2:$B$500,"<="&L8)) | AJ8: =IF(AI8="NOT FOUND","NOT FOUND",INDEX('9_3nf_customer_history'!$C:$C,SUMPRODUCT(('9_3nf_customer_history'!$A$2:$A$500=AD8)*('9_3nf_customer_history'!$B$2:$B$500=AI8)*ROW('9_3nf_customer_history'!$A$2:$A$500)))) | AK8: =IF(AI8="NOT FOUND","NOT FOUND",INDEX('9_3nf_customer_history'!$D:$D,SUMPRODUCT(('9_3nf_customer_history'!$A$2:$A$500=AD8)*('9_3nf_customer_history'!$B$2:$B$500=AI8)*ROW('9_3nf_customer_history'!$A$2:$A$500)))) | AL8: =UPPER(TRIM(H8)) | AM8: =IF(_xlfn.MAXIFS('10_ref_fx_rate'!$B$2:$B$2000,'10_ref_fx_rate'!$A$2:$A$2000,AL8,'10_ref_fx_rate'!$B$2:$B$2000,"<="&L8)=0,"NOT FOUND",_xlfn.MAXIFS('10_ref_fx_rate'!$B$2:$B$2000,'10_ref_fx_rate'!$A$2:$A$2000,AL8,'10_ref_fx_rate'!$B$2:$B$2000,"<="&L8)) | AN8: =IF(AM8="NOT FOUND","NOT FOUND",SUMIFS('10_ref_fx_rate'!$D$2:$D$2000,'10_ref_fx_rate'!$A$2:$A$2000,AL8,'10_ref_fx_rate'!$B$2:$B$2000,AM8)) | AO8: =IF(ISNUMBER(AN8),I8*AN8,"NOT FOUND") | AP8: =UPPER(TRIM(J8)) | AQ8: =IF(AP8="","SELF-DIRECTED",IF(ISNUMBER(MATCH(AP8,'11_3nf_sales_person'!$A:$A,0)),IF(EXACT(AP8,J8),"OK","OK (auto-fixed)"),IF(ISNA(MATCH($A8,'12_sales_person_confirmation'!$A:$A,0)),"CONFIRM (not logged)",IF(INDEX('12_sales_person_confirmation'!$I:$I,MATCH($A8,'12_sales_person_confirmation'!$A:$A,0))="CONFIRMED","CONFIRMED ("&LOWER(INDEX('12_sales_person_confirmation'!$E:$E,MATCH($A8,'12_sales_person_confirmation'!$A:$A,0)))&")","PENDING CONFIRM")))) | AR8: =IF(OR(AQ8="OK",AQ8="OK (auto-fixed)"),AP8,IF(LEFT(AQ8,9)="CONFIRMED",INDEX('12_sales_person_confirmation'!$F:$F,MATCH($A8,'12_sales_person_confirmation'!$A:$A,0)),"")) | AS8: =IF(AR8="","",INDEX('11_3nf_sales_person'!$B:$B,MATCH(AR8,'11_3nf_sales_person'!$A:$A,0)))
A9: =IF(ISBLANK('1_raw_log'!A9),"",'1_raw_log'!A9) | B9: =IF(ISBLANK('1_raw_log'!B9),"",'1_raw_log'!B9) | C9: =IF(ISBLANK('1_raw_log'!C9),"",'1_raw_log'!C9) | D9: =IF(ISBLANK('1_raw_log'!D9),"",'1_raw_log'!D9) | E9: =IF(ISBLANK('1_raw_log'!E9),"",'1_raw_log'!E9) | F9: =IF(ISBLANK('1_raw_log'!F9),"",'1_raw_log'!F9) | G9: =IF(ISBLANK('1_raw_log'!G9),"",'1_raw_log'!G9) | H9: =IF(ISBLANK('1_raw_log'!H9),"",'1_raw_log'!H9) | ... K9: =IF(ISBLANK('1_raw_log'!K9),"",'1_raw_log'!K9) | L9: =INT(B9) | M9: =ROUND(MOD(B9,1)*1440,0)/1440 | N9: =IFERROR(INDEX('3_ref_date'!$B:$B,MATCH(L9,'3_ref_date'!$A:$A,0)),"NOT FOUND") | O9: =IFERROR(INDEX('3_ref_date'!$C:$C,MATCH(L9,'3_ref_date'!$A:$A,0)),"NOT FOUND") | P9: =IFERROR(INDEX('3_ref_date'!$D:$D,MATCH(L9,'3_ref_date'!$A:$A,0)),"NOT FOUND") | Q9: =IFERROR(INDEX('3_ref_date'!$E:$E,MATCH(L9,'3_ref_date'!$A:$A,0)),"NOT FOUND") | R9: =IFERROR(INDEX('3_ref_date'!$F:$F,MATCH(L9,'3_ref_date'!$A:$A,0)),"NOT FOUND") | S9: =IFERROR(INDEX('4_ref_time'!$D:$D,MATCH(ROUND(M9*1440,0),'4_ref_time'!$A:$A,0)),"NOT FOUND") | T9: =UPPER(TRIM(C9)) | U9: =IF(_xlfn.MAXIFS('6_3nf_branch_history'!$B$2:$B$50,'6_3nf_branch_history'!$A$2:$A$50,T9,'6_3nf_branch_history'!$B$2:$B$50,"<="&L9)=0,"NOT FOUND",_xlfn.MAXIFS('6_3nf_branch_history'!$B$2:$B$50,'6_3nf_branch_history'!$A$2:$A$50,T9,'6_3nf_branch_history'!$B$2:$B$50,"<="&L9)) | V9: =IF(U9="NOT FOUND","NOT FOUND",INDEX('6_3nf_branch_history'!$C:$C,SUMPRODUCT(('6_3nf_branch_history'!$A$2:$A$50=T9)*('6_3nf_branch_history'!$B$2:$B$50=U9)*ROW('6_3nf_branch_history'!$A$2:$A$50)))) | W9: =IF(U9="NOT FOUND","NOT FOUND",INDEX('6_3nf_branch_history'!$D:$D,SUMPRODUCT(('6_3nf_branch_history'!$A$2:$A$50=T9)*('6_3nf_branch_history'!$B$2:$B$50=U9)*ROW('6_3nf_branch_history'!$A$2:$A$50)))) | X9: =IF(U9="NOT FOUND","NOT FOUND",INDEX('6_3nf_branch_history'!$E:$E,SUMPRODUCT(('6_3nf_branch_history'!$A$2:$A$50=T9)*('6_3nf_branch_history'!$B$2:$B$50=U9)*ROW('6_3nf_branch_history'!$A$2:$A$50)))) | Y9: =UPPER(TRIM(D9)) | Z9: =IFERROR(INDEX('7_3nf_product'!$B:$B,MATCH(Y9,'7_3nf_product'!$A:$A,0)),"NOT FOUND") | AA9: =IFERROR(INDEX('7_3nf_product'!$C:$C,MATCH(Y9,'7_3nf_product'!$A:$A,0)),"NOT FOUND") | AB9: =IFERROR(INDEX('7_3nf_product'!$D:$D,MATCH(Y9,'7_3nf_product'!$A:$A,0)),"NOT FOUND") | AC9: =IFERROR(INDEX('7_3nf_product'!$E:$E,MATCH(Y9,'7_3nf_product'!$A:$A,0)),"NOT FOUND") | AD9: =IF(LEN(TRIM(E9))=10,TRIM(E9),IF(LEN(TRIM(E9))=8,"00"&TRIM(E9),"CHECK")) | AE9: =IFERROR(INDEX('8_3nf_customer'!$C:$C,MATCH(AD9,'8_3nf_customer'!$B:$B,0)),"NOT FOUND") | AF9: =IFERROR(INDEX('8_3nf_customer'!$D:$D,MATCH(AD9,'8_3nf_customer'!$B:$B,0)),"NOT FOUND") | AG9: =IF(ISNUMBER(AF9),DATEDIF(AF9,L9,"y"),"NOT FOUND") | AH9: =IFERROR(INDEX('8_3nf_customer'!$E:$E,MATCH(AD9,'8_3nf_customer'!$B:$B,0)),"NOT FOUND") | AI9: =IF(_xlfn.MAXIFS('9_3nf_customer_history'!$B$2:$B$500,'9_3nf_customer_history'!$A$2:$A$500,AD9,'9_3nf_customer_history'!$B$2:$B$500,"<="&L9)=0,"NOT FOUND",_xlfn.MAXIFS('9_3nf_customer_history'!$B$2:$B$500,'9_3nf_customer_history'!$A$2:$A$500,AD9,'9_3nf_customer_history'!$B$2:$B$500,"<="&L9)) | AJ9: =IF(AI9="NOT FOUND","NOT FOUND",INDEX('9_3nf_customer_history'!$C:$C,SUMPRODUCT(('9_3nf_customer_history'!$A$2:$A$500=AD9)*('9_3nf_customer_history'!$B$2:$B$500=AI9)*ROW('9_3nf_customer_history'!$A$2:$A$500)))) | AK9: =IF(AI9="NOT FOUND","NOT FOUND",INDEX('9_3nf_customer_history'!$D:$D,SUMPRODUCT(('9_3nf_customer_history'!$A$2:$A$500=AD9)*('9_3nf_customer_history'!$B$2:$B$500=AI9)*ROW('9_3nf_customer_history'!$A$2:$A$500)))) | AL9: =UPPER(TRIM(H9)) | AM9: =IF(_xlfn.MAXIFS('10_ref_fx_rate'!$B$2:$B$2000,'10_ref_fx_rate'!$A$2:$A$2000,AL9,'10_ref_fx_rate'!$B$2:$B$2000,"<="&L9)=0,"NOT FOUND",_xlfn.MAXIFS('10_ref_fx_rate'!$B$2:$B$2000,'10_ref_fx_rate'!$A$2:$A$2000,AL9,'10_ref_fx_rate'!$B$2:$B$2000,"<="&L9)) | AN9: =IF(AM9="NOT FOUND","NOT FOUND",SUMIFS('10_ref_fx_rate'!$D$2:$D$2000,'10_ref_fx_rate'!$A$2:$A$2000,AL9,'10_ref_fx_rate'!$B$2:$B$2000,AM9)) | AO9: =IF(ISNUMBER(AN9),I9*AN9,"NOT FOUND") | AP9: =UPPER(TRIM(J9)) | AQ9: =IF(AP9="","SELF-DIRECTED",IF(ISNUMBER(MATCH(AP9,'11_3nf_sales_person'!$A:$A,0)),IF(EXACT(AP9,J9),"OK","OK (auto-fixed)"),IF(ISNA(MATCH($A9,'12_sales_person_confirmation'!$A:$A,0)),"CONFIRM (not logged)",IF(INDEX('12_sales_person_confirmation'!$I:$I,MATCH($A9,'12_sales_person_confirmation'!$A:$A,0))="CONFIRMED","CONFIRMED ("&LOWER(INDEX('12_sales_person_confirmation'!$E:$E,MATCH($A9,'12_sales_person_confirmation'!$A:$A,0)))&")","PENDING CONFIRM")))) | AR9: =IF(OR(AQ9="OK",AQ9="OK (auto-fixed)"),AP9,IF(LEFT(AQ9,9)="CONFIRMED",INDEX('12_sales_person_confirmation'!$F:$F,MATCH($A9,'12_sales_person_confirmation'!$A:$A,0)),"")) | AS9: =IF(AR9="","",INDEX('11_3nf_sales_person'!$B:$B,MATCH(AR9,'11_3nf_sales_person'!$A:$A,0)))
A10: =IF(ISBLANK('1_raw_log'!A10),"",'1_raw_log'!A10) | B10: =IF(ISBLANK('1_raw_log'!B10),"",'1_raw_log'!B10) | C10: =IF(ISBLANK('1_raw_log'!C10),"",'1_raw_log'!C10) | D10: =IF(ISBLANK('1_raw_log'!D10),"",'1_raw_log'!D10) | E10: =IF(ISBLANK('1_raw_log'!E10),"",'1_raw_log'!E10) | F10: =IF(ISBLANK('1_raw_log'!F10),"",'1_raw_log'!F10) | G10: =IF(ISBLANK('1_raw_log'!G10),"",'1_raw_log'!G10) | H10: =IF(ISBLANK('1_raw_log'!H10),"",'1_raw_log'!H10) | ... K10: =IF(ISBLANK('1_raw_log'!K10),"",'1_raw_log'!K10) | L10: =INT(B10) | M10: =ROUND(MOD(B10,1)*1440,0)/1440 | N10: =IFERROR(INDEX('3_ref_date'!$B:$B,MATCH(L10,'3_ref_date'!$A:$A,0)),"NOT FOUND") | O10: =IFERROR(INDEX('3_ref_date'!$C:$C,MATCH(L10,'3_ref_date'!$A:$A,0)),"NOT FOUND") | P10: =IFERROR(INDEX('3_ref_date'!$D:$D,MATCH(L10,'3_ref_date'!$A:$A,0)),"NOT FOUND") | Q10: =IFERROR(INDEX('3_ref_date'!$E:$E,MATCH(L10,'3_ref_date'!$A:$A,0)),"NOT FOUND") | R10: =IFERROR(INDEX('3_ref_date'!$F:$F,MATCH(L10,'3_ref_date'!$A:$A,0)),"NOT FOUND") | S10: =IFERROR(INDEX('4_ref_time'!$D:$D,MATCH(ROUND(M10*1440,0),'4_ref_time'!$A:$A,0)),"NOT FOUND") | T10: =UPPER(TRIM(C10)) | U10: =IF(_xlfn.MAXIFS('6_3nf_branch_history'!$B$2:$B$50,'6_3nf_branch_history'!$A$2:$A$50,T10,'6_3nf_branch_history'!$B$2:$B$50,"<="&L10)=0,"NOT FOUND",_xlfn.MAXIFS('6_3nf_branch_history'!$B$2:$B$50,'6_3nf_branch_history'!$A$2:$A$50,T10,'6_3nf_branch_history'!$B$2:$B$50,"<="&L10)) | V10: =IF(U10="NOT FOUND","NOT FOUND",INDEX('6_3nf_branch_history'!$C:$C,SUMPRODUCT(('6_3nf_branch_history'!$A$2:$A$50=T10)*('6_3nf_branch_history'!$B$2:$B$50=U10)*ROW('6_3nf_branch_history'!$A$2:$A$50)))) | W10: =IF(U10="NOT FOUND","NOT FOUND",INDEX('6_3nf_branch_history'!$D:$D,SUMPRODUCT(('6_3nf_branch_history'!$A$2:$A$50=T10)*('6_3nf_branch_history'!$B$2:$B$50=U10)*ROW('6_3nf_branch_history'!$A$2:$A$50)))) | X10: =IF(U10="NOT FOUND","NOT FOUND",INDEX('6_3nf_branch_history'!$E:$E,SUMPRODUCT(('6_3nf_branch_history'!$A$2:$A$50=T10)*('6_3nf_branch_history'!$B$2:$B$50=U10)*ROW('6_3nf_branch_history'!$A$2:$A$50)))) | Y10: =UPPER(TRIM(D10)) | Z10: =IFERROR(INDEX('7_3nf_product'!$B:$B,MATCH(Y10,'7_3nf_product'!$A:$A,0)),"NOT FOUND") | AA10: =IFERROR(INDEX('7_3nf_product'!$C:$C,MATCH(Y10,'7_3nf_product'!$A:$A,0)),"NOT FOUND") | AB10: =IFERROR(INDEX('7_3nf_product'!$D:$D,MATCH(Y10,'7_3nf_product'!$A:$A,0)),"NOT FOUND") | AC10: =IFERROR(INDEX('7_3nf_product'!$E:$E,MATCH(Y10,'7_3nf_product'!$A:$A,0)),"NOT FOUND") | AD10: =IF(LEN(TRIM(E10))=10,TRIM(E10),IF(LEN(TRIM(E10))=8,"00"&TRIM(E10),"CHECK")) | AE10: =IFERROR(INDEX('8_3nf_customer'!$C:$C,MATCH(AD10,'8_3nf_customer'!$B:$B,0)),"NOT FOUND") | AF10: =IFERROR(INDEX('8_3nf_customer'!$D:$D,MATCH(AD10,'8_3nf_customer'!$B:$B,0)),"NOT FOUND") | AG10: =IF(ISNUMBER(AF10),DATEDIF(AF10,L10,"y"),"NOT FOUND") | AH10: =IFERROR(INDEX('8_3nf_customer'!$E:$E,MATCH(AD10,'8_3nf_customer'!$B:$B,0)),"NOT FOUND") | AI10: =IF(_xlfn.MAXIFS('9_3nf_customer_history'!$B$2:$B$500,'9_3nf_customer_history'!$A$2:$A$500,AD10,'9_3nf_customer_history'!$B$2:$B$500,"<="&L10)=0,"NOT FOUND",_xlfn.MAXIFS('9_3nf_customer_history'!$B$2:$B$500,'9_3nf_customer_history'!$A$2:$A$500,AD10,'9_3nf_customer_history'!$B$2:$B$500,"<="&L10)) | AJ10: =IF(AI10="NOT FOUND","NOT FOUND",INDEX('9_3nf_customer_history'!$C:$C,SUMPRODUCT(('9_3nf_customer_history'!$A$2:$A$500=AD10)*('9_3nf_customer_history'!$B$2:$B$500=AI10)*ROW('9_3nf_customer_history'!$A$2:$A$500)))) | AK10: =IF(AI10="NOT FOUND","NOT FOUND",INDEX('9_3nf_customer_history'!$D:$D,SUMPRODUCT(('9_3nf_customer_history'!$A$2:$A$500=AD10)*('9_3nf_customer_history'!$B$2:$B$500=AI10)*ROW('9_3nf_customer_history'!$A$2:$A$500)))) | AL10: =UPPER(TRIM(H10)) | AM10: =IF(_xlfn.MAXIFS('10_ref_fx_rate'!$B$2:$B$2000,'10_ref_fx_rate'!$A$2:$A$2000,AL10,'10_ref_fx_rate'!$B$2:$B$2000,"<="&L10)=0,"NOT FOUND",_xlfn.MAXIFS('10_ref_fx_rate'!$B$2:$B$2000,'10_ref_fx_rate'!$A$2:$A$2000,AL10,'10_ref_fx_rate'!$B$2:$B$2000,"<="&L10)) | AN10: =IF(AM10="NOT FOUND","NOT FOUND",SUMIFS('10_ref_fx_rate'!$D$2:$D$2000,'10_ref_fx_rate'!$A$2:$A$2000,AL10,'10_ref_fx_rate'!$B$2:$B$2000,AM10)) | AO10: =IF(ISNUMBER(AN10),I10*AN10,"NOT FOUND") | AP10: =UPPER(TRIM(J10)) | AQ10: =IF(AP10="","SELF-DIRECTED",IF(ISNUMBER(MATCH(AP10,'11_3nf_sales_person'!$A:$A,0)),IF(EXACT(AP10,J10),"OK","OK (auto-fixed)"),IF(ISNA(MATCH($A10,'12_sales_person_confirmation'!$A:$A,0)),"CONFIRM (not logged)",IF(INDEX('12_sales_person_confirmation'!$I:$I,MATCH($A10,'12_sales_person_confirmation'!$A:$A,0))="CONFIRMED","CONFIRMED ("&LOWER(INDEX('12_sales_person_confirmation'!$E:$E,MATCH($A10,'12_sales_person_confirmation'!$A:$A,0)))&")","PENDING CONFIRM")))) | AR10: =IF(OR(AQ10="OK",AQ10="OK (auto-fixed)"),AP10,IF(LEFT(AQ10,9)="CONFIRMED",INDEX('12_sales_person_confirmation'!$F:$F,MATCH($A10,'12_sales_person_confirmation'!$A:$A,0)),"")) | AS10: =IF(AR10="","",INDEX('11_3nf_sales_person'!$B:$B,MATCH(AR10,'11_3nf_sales_person'!$A:$A,0)))
A11: =IF(ISBLANK('1_raw_log'!A11),"",'1_raw_log'!A11) | B11: =IF(ISBLANK('1_raw_log'!B11),"",'1_raw_log'!B11) | C11: =IF(ISBLANK('1_raw_log'!C11),"",'1_raw_log'!C11) | D11: =IF(ISBLANK('1_raw_log'!D11),"",'1_raw_log'!D11) | E11: =IF(ISBLANK('1_raw_log'!E11),"",'1_raw_log'!E11) | F11: =IF(ISBLANK('1_raw_log'!F11),"",'1_raw_log'!F11) | G11: =IF(ISBLANK('1_raw_log'!G11),"",'1_raw_log'!G11) | H11: =IF(ISBLANK('1_raw_log'!H11),"",'1_raw_log'!H11) | ... K11: =IF(ISBLANK('1_raw_log'!K11),"",'1_raw_log'!K11) | L11: =INT(B11) | M11: =ROUND(MOD(B11,1)*1440,0)/1440 | N11: =IFERROR(INDEX('3_ref_date'!$B:$B,MATCH(L11,'3_ref_date'!$A:$A,0)),"NOT FOUND") | O11: =IFERROR(INDEX('3_ref_date'!$C:$C,MATCH(L11,'3_ref_date'!$A:$A,0)),"NOT FOUND") | P11: =IFERROR(INDEX('3_ref_date'!$D:$D,MATCH(L11,'3_ref_date'!$A:$A,0)),"NOT FOUND") | Q11: =IFERROR(INDEX('3_ref_date'!$E:$E,MATCH(L11,'3_ref_date'!$A:$A,0)),"NOT FOUND") | R11: =IFERROR(INDEX('3_ref_date'!$F:$F,MATCH(L11,'3_ref_date'!$A:$A,0)),"NOT FOUND") | S11: =IFERROR(INDEX('4_ref_time'!$D:$D,MATCH(ROUND(M11*1440,0),'4_ref_time'!$A:$A,0)),"NOT FOUND") | T11: =UPPER(TRIM(C11)) | U11: =IF(_xlfn.MAXIFS('6_3nf_branch_history'!$B$2:$B$50,'6_3nf_branch_history'!$A$2:$A$50,T11,'6_3nf_branch_history'!$B$2:$B$50,"<="&L11)=0,"NOT FOUND",_xlfn.MAXIFS('6_3nf_branch_history'!$B$2:$B$50,'6_3nf_branch_history'!$A$2:$A$50,T11,'6_3nf_branch_history'!$B$2:$B$50,"<="&L11)) | V11: =IF(U11="NOT FOUND","NOT FOUND",INDEX('6_3nf_branch_history'!$C:$C,SUMPRODUCT(('6_3nf_branch_history'!$A$2:$A$50=T11)*('6_3nf_branch_history'!$B$2:$B$50=U11)*ROW('6_3nf_branch_history'!$A$2:$A$50)))) | W11: =IF(U11="NOT FOUND","NOT FOUND",INDEX('6_3nf_branch_history'!$D:$D,SUMPRODUCT(('6_3nf_branch_history'!$A$2:$A$50=T11)*('6_3nf_branch_history'!$B$2:$B$50=U11)*ROW('6_3nf_branch_history'!$A$2:$A$50)))) | X11: =IF(U11="NOT FOUND","NOT FOUND",INDEX('6_3nf_branch_history'!$E:$E,SUMPRODUCT(('6_3nf_branch_history'!$A$2:$A$50=T11)*('6_3nf_branch_history'!$B$2:$B$50=U11)*ROW('6_3nf_branch_history'!$A$2:$A$50)))) | Y11: =UPPER(TRIM(D11)) | Z11: =IFERROR(INDEX('7_3nf_product'!$B:$B,MATCH(Y11,'7_3nf_product'!$A:$A,0)),"NOT FOUND") | AA11: =IFERROR(INDEX('7_3nf_product'!$C:$C,MATCH(Y11,'7_3nf_product'!$A:$A,0)),"NOT FOUND") | AB11: =IFERROR(INDEX('7_3nf_product'!$D:$D,MATCH(Y11,'7_3nf_product'!$A:$A,0)),"NOT FOUND") | AC11: =IFERROR(INDEX('7_3nf_product'!$E:$E,MATCH(Y11,'7_3nf_product'!$A:$A,0)),"NOT FOUND") | AD11: =IF(LEN(TRIM(E11))=10,TRIM(E11),IF(LEN(TRIM(E11))=8,"00"&TRIM(E11),"CHECK")) | AE11: =IFERROR(INDEX('8_3nf_customer'!$C:$C,MATCH(AD11,'8_3nf_customer'!$B:$B,0)),"NOT FOUND") | AF11: =IFERROR(INDEX('8_3nf_customer'!$D:$D,MATCH(AD11,'8_3nf_customer'!$B:$B,0)),"NOT FOUND") | AG11: =IF(ISNUMBER(AF11),DATEDIF(AF11,L11,"y"),"NOT FOUND") | AH11: =IFERROR(INDEX('8_3nf_customer'!$E:$E,MATCH(AD11,'8_3nf_customer'!$B:$B,0)),"NOT FOUND") | AI11: =IF(_xlfn.MAXIFS('9_3nf_customer_history'!$B$2:$B$500,'9_3nf_customer_history'!$A$2:$A$500,AD11,'9_3nf_customer_history'!$B$2:$B$500,"<="&L11)=0,"NOT FOUND",_xlfn.MAXIFS('9_3nf_customer_history'!$B$2:$B$500,'9_3nf_customer_history'!$A$2:$A$500,AD11,'9_3nf_customer_history'!$B$2:$B$500,"<="&L11)) | AJ11: =IF(AI11="NOT FOUND","NOT FOUND",INDEX('9_3nf_customer_history'!$C:$C,SUMPRODUCT(('9_3nf_customer_history'!$A$2:$A$500=AD11)*('9_3nf_customer_history'!$B$2:$B$500=AI11)*ROW('9_3nf_customer_history'!$A$2:$A$500)))) | AK11: =IF(AI11="NOT FOUND","NOT FOUND",INDEX('9_3nf_customer_history'!$D:$D,SUMPRODUCT(('9_3nf_customer_history'!$A$2:$A$500=AD11)*('9_3nf_customer_history'!$B$2:$B$500=AI11)*ROW('9_3nf_customer_history'!$A$2:$A$500)))) | AL11: =UPPER(TRIM(H11)) | AM11: =IF(_xlfn.MAXIFS('10_ref_fx_rate'!$B$2:$B$2000,'10_ref_fx_rate'!$A$2:$A$2000,AL11,'10_ref_fx_rate'!$B$2:$B$2000,"<="&L11)=0,"NOT FOUND",_xlfn.MAXIFS('10_ref_fx_rate'!$B$2:$B$2000,'10_ref_fx_rate'!$A$2:$A$2000,AL11,'10_ref_fx_rate'!$B$2:$B$2000,"<="&L11)) | AN11: =IF(AM11="NOT FOUND","NOT FOUND",SUMIFS('10_ref_fx_rate'!$D$2:$D$2000,'10_ref_fx_rate'!$A$2:$A$2000,AL11,'10_ref_fx_rate'!$B$2:$B$2000,AM11)) | AO11: =IF(ISNUMBER(AN11),I11*AN11,"NOT FOUND") | AP11: =UPPER(TRIM(J11)) | AQ11: =IF(AP11="","SELF-DIRECTED",IF(ISNUMBER(MATCH(AP11,'11_3nf_sales_person'!$A:$A,0)),IF(EXACT(AP11,J11),"OK","OK (auto-fixed)"),IF(ISNA(MATCH($A11,'12_sales_person_confirmation'!$A:$A,0)),"CONFIRM (not logged)",IF(INDEX('12_sales_person_confirmation'!$I:$I,MATCH($A11,'12_sales_person_confirmation'!$A:$A,0))="CONFIRMED","CONFIRMED ("&LOWER(INDEX('12_sales_person_confirmation'!$E:$E,MATCH($A11,'12_sales_person_confirmation'!$A:$A,0)))&")","PENDING CONFIRM")))) | AR11: =IF(OR(AQ11="OK",AQ11="OK (auto-fixed)"),AP11,IF(LEFT(AQ11,9)="CONFIRMED",INDEX('12_sales_person_confirmation'!$F:$F,MATCH($A11,'12_sales_person_confirmation'!$A:$A,0)),"")) | AS11: =IF(AR11="","",INDEX('11_3nf_sales_person'!$B:$B,MATCH(AR11,'11_3nf_sales_person'!$A:$A,0)))
A12: =IF(ISBLANK('1_raw_log'!A12),"",'1_raw_log'!A12) | B12: =IF(ISBLANK('1_raw_log'!B12),"",'1_raw_log'!B12) | C12: =IF(ISBLANK('1_raw_log'!C12),"",'1_raw_log'!C12) | D12: =IF(ISBLANK('1_raw_log'!D12),"",'1_raw_log'!D12) | E12: =IF(ISBLANK('1_raw_log'!E12),"",'1_raw_log'!E12) | F12: =IF(ISBLANK('1_raw_log'!F12),"",'1_raw_log'!F12) | G12: =IF(ISBLANK('1_raw_log'!G12),"",'1_raw_log'!G12) | H12: =IF(ISBLANK('1_raw_log'!H12),"",'1_raw_log'!H12) | ... K12: =IF(ISBLANK('1_raw_log'!K12),"",'1_raw_log'!K12) | L12: =INT(B12) | M12: =ROUND(MOD(B12,1)*1440,0)/1440 | N12: =IFERROR(INDEX('3_ref_date'!$B:$B,MATCH(L12,'3_ref_date'!$A:$A,0)),"NOT FOUND") | O12: =IFERROR(INDEX('3_ref_date'!$C:$C,MATCH(L12,'3_ref_date'!$A:$A,0)),"NOT FOUND") | P12: =IFERROR(INDEX('3_ref_date'!$D:$D,MATCH(L12,'3_ref_date'!$A:$A,0)),"NOT FOUND") | Q12: =IFERROR(INDEX('3_ref_date'!$E:$E,MATCH(L12,'3_ref_date'!$A:$A,0)),"NOT FOUND") | R12: =IFERROR(INDEX('3_ref_date'!$F:$F,MATCH(L12,'3_ref_date'!$A:$A,0)),"NOT FOUND") | S12: =IFERROR(INDEX('4_ref_time'!$D:$D,MATCH(ROUND(M12*1440,0),'4_ref_time'!$A:$A,0)),"NOT FOUND") | T12: =UPPER(TRIM(C12)) | U12: =IF(_xlfn.MAXIFS('6_3nf_branch_history'!$B$2:$B$50,'6_3nf_branch_history'!$A$2:$A$50,T12,'6_3nf_branch_history'!$B$2:$B$50,"<="&L12)=0,"NOT FOUND",_xlfn.MAXIFS('6_3nf_branch_history'!$B$2:$B$50,'6_3nf_branch_history'!$A$2:$A$50,T12,'6_3nf_branch_history'!$B$2:$B$50,"<="&L12)) | V12: =IF(U12="NOT FOUND","NOT FOUND",INDEX('6_3nf_branch_history'!$C:$C,SUMPRODUCT(('6_3nf_branch_history'!$A$2:$A$50=T12)*('6_3nf_branch_history'!$B$2:$B$50=U12)*ROW('6_3nf_branch_history'!$A$2:$A$50)))) | W12: =IF(U12="NOT FOUND","NOT FOUND",INDEX('6_3nf_branch_history'!$D:$D,SUMPRODUCT(('6_3nf_branch_history'!$A$2:$A$50=T12)*('6_3nf_branch_history'!$B$2:$B$50=U12)*ROW('6_3nf_branch_history'!$A$2:$A$50)))) | X12: =IF(U12="NOT FOUND","NOT FOUND",INDEX('6_3nf_branch_history'!$E:$E,SUMPRODUCT(('6_3nf_branch_history'!$A$2:$A$50=T12)*('6_3nf_branch_history'!$B$2:$B$50=U12)*ROW('6_3nf_branch_history'!$A$2:$A$50)))) | Y12: =UPPER(TRIM(D12)) | Z12: =IFERROR(INDEX('7_3nf_product'!$B:$B,MATCH(Y12,'7_3nf_product'!$A:$A,0)),"NOT FOUND") | AA12: =IFERROR(INDEX('7_3nf_product'!$C:$C,MATCH(Y12,'7_3nf_product'!$A:$A,0)),"NOT FOUND") | AB12: =IFERROR(INDEX('7_3nf_product'!$D:$D,MATCH(Y12,'7_3nf_product'!$A:$A,0)),"NOT FOUND") | AC12: =IFERROR(INDEX('7_3nf_product'!$E:$E,MATCH(Y12,'7_3nf_product'!$A:$A,0)),"NOT FOUND") | AD12: =IF(LEN(TRIM(E12))=10,TRIM(E12),IF(LEN(TRIM(E12))=8,"00"&TRIM(E12),"CHECK")) | AE12: =IFERROR(INDEX('8_3nf_customer'!$C:$C,MATCH(AD12,'8_3nf_customer'!$B:$B,0)),"NOT FOUND") | AF12: =IFERROR(INDEX('8_3nf_customer'!$D:$D,MATCH(AD12,'8_3nf_customer'!$B:$B,0)),"NOT FOUND") | AG12: =IF(ISNUMBER(AF12),DATEDIF(AF12,L12,"y"),"NOT FOUND") | AH12: =IFERROR(INDEX('8_3nf_customer'!$E:$E,MATCH(AD12,'8_3nf_customer'!$B:$B,0)),"NOT FOUND") | AI12: =IF(_xlfn.MAXIFS('9_3nf_customer_history'!$B$2:$B$500,'9_3nf_customer_history'!$A$2:$A$500,AD12,'9_3nf_customer_history'!$B$2:$B$500,"<="&L12)=0,"NOT FOUND",_xlfn.MAXIFS('9_3nf_customer_history'!$B$2:$B$500,'9_3nf_customer_history'!$A$2:$A$500,AD12,'9_3nf_customer_history'!$B$2:$B$500,"<="&L12)) | AJ12: =IF(AI12="NOT FOUND","NOT FOUND",INDEX('9_3nf_customer_history'!$C:$C,SUMPRODUCT(('9_3nf_customer_history'!$A$2:$A$500=AD12)*('9_3nf_customer_history'!$B$2:$B$500=AI12)*ROW('9_3nf_customer_history'!$A$2:$A$500)))) | AK12: =IF(AI12="NOT FOUND","NOT FOUND",INDEX('9_3nf_customer_history'!$D:$D,SUMPRODUCT(('9_3nf_customer_history'!$A$2:$A$500=AD12)*('9_3nf_customer_history'!$B$2:$B$500=AI12)*ROW('9_3nf_customer_history'!$A$2:$A$500)))) | AL12: =UPPER(TRIM(H12)) | AM12: =IF(_xlfn.MAXIFS('10_ref_fx_rate'!$B$2:$B$2000,'10_ref_fx_rate'!$A$2:$A$2000,AL12,'10_ref_fx_rate'!$B$2:$B$2000,"<="&L12)=0,"NOT FOUND",_xlfn.MAXIFS('10_ref_fx_rate'!$B$2:$B$2000,'10_ref_fx_rate'!$A$2:$A$2000,AL12,'10_ref_fx_rate'!$B$2:$B$2000,"<="&L12)) | AN12: =IF(AM12="NOT FOUND","NOT FOUND",SUMIFS('10_ref_fx_rate'!$D$2:$D$2000,'10_ref_fx_rate'!$A$2:$A$2000,AL12,'10_ref_fx_rate'!$B$2:$B$2000,AM12)) | AO12: =IF(ISNUMBER(AN12),I12*AN12,"NOT FOUND") | AP12: =UPPER(TRIM(J12)) | AQ12: =IF(AP12="","SELF-DIRECTED",IF(ISNUMBER(MATCH(AP12,'11_3nf_sales_person'!$A:$A,0)),IF(EXACT(AP12,J12),"OK","OK (auto-fixed)"),IF(ISNA(MATCH($A12,'12_sales_person_confirmation'!$A:$A,0)),"CONFIRM (not logged)",IF(INDEX('12_sales_person_confirmation'!$I:$I,MATCH($A12,'12_sales_person_confirmation'!$A:$A,0))="CONFIRMED","CONFIRMED ("&LOWER(INDEX('12_sales_person_confirmation'!$E:$E,MATCH($A12,'12_sales_person_confirmation'!$A:$A,0)))&")","PENDING CONFIRM")))) | AR12: =IF(OR(AQ12="OK",AQ12="OK (auto-fixed)"),AP12,IF(LEFT(AQ12,9)="CONFIRMED",INDEX('12_sales_person_confirmation'!$F:$F,MATCH($A12,'12_sales_person_confirmation'!$A:$A,0)),"")) | AS12: =IF(AR12="","",INDEX('11_3nf_sales_person'!$B:$B,MATCH(AR12,'11_3nf_sales_person'!$A:$A,0)))
